2022-05-19 17:03:04,851 INFO    MainThread:10068 [internal.py:wandb_internal():90] W&B internal server running at pid: 10068, started at: 2022-05-19 17:03:04.851578
2022-05-19 17:03:04,854 INFO    WriterThread:10068 [datastore.py:open_for_write():75] open: /home/hikari007/dl-torch/Classification/VGGNet/wandb/run-20220519_170304-188kmhvw/run-188kmhvw.wandb
2022-05-19 17:03:04,856 DEBUG   SenderThread:10068 [sender.py:send():232] send: header
2022-05-19 17:03:04,856 DEBUG   SenderThread:10068 [sender.py:send():232] send: run
2022-05-19 17:03:08,138 ERROR   SenderThread:10068 [retry.py:__call__():126] Retry attempt failed:
Traceback (most recent call last):
  File "/home/hikari007/miniconda3/envs/d2l/lib/python3.8/site-packages/urllib3/connection.py", line 174, in _new_conn
    conn = connection.create_connection(
  File "/home/hikari007/miniconda3/envs/d2l/lib/python3.8/site-packages/urllib3/util/connection.py", line 72, in create_connection
    for res in socket.getaddrinfo(host, port, family, socket.SOCK_STREAM):
  File "/home/hikari007/miniconda3/envs/d2l/lib/python3.8/socket.py", line 918, in getaddrinfo
    for res in _socket.getaddrinfo(host, port, family, type, proto, flags):
socket.gaierror: [Errno -3] Temporary failure in name resolution

During handling of the above exception, another exception occurred:

Traceback (most recent call last):
  File "/home/hikari007/miniconda3/envs/d2l/lib/python3.8/site-packages/urllib3/connectionpool.py", line 703, in urlopen
    httplib_response = self._make_request(
  File "/home/hikari007/miniconda3/envs/d2l/lib/python3.8/site-packages/urllib3/connectionpool.py", line 386, in _make_request
    self._validate_conn(conn)
  File "/home/hikari007/miniconda3/envs/d2l/lib/python3.8/site-packages/urllib3/connectionpool.py", line 1040, in _validate_conn
    conn.connect()
  File "/home/hikari007/miniconda3/envs/d2l/lib/python3.8/site-packages/urllib3/connection.py", line 358, in connect
    self.sock = conn = self._new_conn()
  File "/home/hikari007/miniconda3/envs/d2l/lib/python3.8/site-packages/urllib3/connection.py", line 186, in _new_conn
    raise NewConnectionError(
urllib3.exceptions.NewConnectionError: <urllib3.connection.HTTPSConnection object at 0x7fbe78cb00d0>: Failed to establish a new connection: [Errno -3] Temporary failure in name resolution

During handling of the above exception, another exception occurred:

Traceback (most recent call last):
  File "/home/hikari007/miniconda3/envs/d2l/lib/python3.8/site-packages/requests/adapters.py", line 439, in send
    resp = conn.urlopen(
  File "/home/hikari007/miniconda3/envs/d2l/lib/python3.8/site-packages/urllib3/connectionpool.py", line 785, in urlopen
    retries = retries.increment(
  File "/home/hikari007/miniconda3/envs/d2l/lib/python3.8/site-packages/urllib3/util/retry.py", line 592, in increment
    raise MaxRetryError(_pool, url, error or ResponseError(cause))
urllib3.exceptions.MaxRetryError: HTTPSConnectionPool(host='api.wandb.ai', port=443): Max retries exceeded with url: /graphql (Caused by NewConnectionError('<urllib3.connection.HTTPSConnection object at 0x7fbe78cb00d0>: Failed to establish a new connection: [Errno -3] Temporary failure in name resolution'))

During handling of the above exception, another exception occurred:

Traceback (most recent call last):
  File "/home/hikari007/miniconda3/envs/d2l/lib/python3.8/site-packages/wandb/sdk/lib/retry.py", line 102, in __call__
    result = self._call_fn(*args, **kwargs)
  File "/home/hikari007/miniconda3/envs/d2l/lib/python3.8/site-packages/wandb/sdk/internal/internal_api.py", line 140, in execute
    return self.client.execute(*args, **kwargs)
  File "/home/hikari007/miniconda3/envs/d2l/lib/python3.8/site-packages/wandb/vendor/gql-0.2.0/wandb_gql/client.py", line 52, in execute
    result = self._get_result(document, *args, **kwargs)
  File "/home/hikari007/miniconda3/envs/d2l/lib/python3.8/site-packages/wandb/vendor/gql-0.2.0/wandb_gql/client.py", line 60, in _get_result
    return self.transport.execute(document, *args, **kwargs)
  File "/home/hikari007/miniconda3/envs/d2l/lib/python3.8/site-packages/wandb/vendor/gql-0.2.0/wandb_gql/transport/requests.py", line 38, in execute
    request = requests.post(self.url, **post_args)
  File "/home/hikari007/miniconda3/envs/d2l/lib/python3.8/site-packages/requests/api.py", line 119, in post
    return request('post', url, data=data, json=json, **kwargs)
  File "/home/hikari007/miniconda3/envs/d2l/lib/python3.8/site-packages/requests/api.py", line 61, in request
    return session.request(method=method, url=url, **kwargs)
  File "/home/hikari007/miniconda3/envs/d2l/lib/python3.8/site-packages/requests/sessions.py", line 542, in request
    resp = self.send(prep, **send_kwargs)
  File "/home/hikari007/miniconda3/envs/d2l/lib/python3.8/site-packages/requests/sessions.py", line 655, in send
    r = adapter.send(request, **kwargs)
  File "/home/hikari007/miniconda3/envs/d2l/lib/python3.8/site-packages/requests/adapters.py", line 516, in send
    raise ConnectionError(e, request=request)
requests.exceptions.ConnectionError: HTTPSConnectionPool(host='api.wandb.ai', port=443): Max retries exceeded with url: /graphql (Caused by NewConnectionError('<urllib3.connection.HTTPSConnection object at 0x7fbe78cb00d0>: Failed to establish a new connection: [Errno -3] Temporary failure in name resolution'))
2022-05-19 17:03:09,471 WARNING MainThread:10068 [internal.py:wandb_internal():153] Internal process interrupt: 1
2022-05-19 17:03:24,414 WARNING MainThread:10068 [internal.py:wandb_internal():153] Internal process interrupt: 2
2022-05-19 17:03:24,414 ERROR   MainThread:10068 [internal.py:wandb_internal():156] Internal process interrupted.
2022-05-19 17:03:24,860 INFO    WriterThread:10068 [datastore.py:close():279] close: /home/hikari007/dl-torch/Classification/VGGNet/wandb/run-20220519_170304-188kmhvw/run-188kmhvw.wandb
2022-05-19 17:03:24,879 INFO    HandlerThread:10068 [handler.py:finish():806] shutting down handler
2022-05-19 17:04:16,979 INFO    SenderThread:10068 [dir_watcher.py:__init__():166] watching files in: /home/hikari007/dl-torch/Classification/VGGNet/wandb/run-20220519_170304-188kmhvw/files
2022-05-19 17:04:16,979 INFO    SenderThread:10068 [sender.py:_start_run_threads():811] run started: 188kmhvw with start time 1652950984
2022-05-19 17:04:16,979 INFO    SenderThread:10068 [sender.py:finish():1106] shutting down sender
2022-05-19 17:04:16,979 INFO    SenderThread:10068 [dir_watcher.py:finish():279] shutting down directory watcher
2022-05-19 17:04:17,979 INFO    SenderThread:10068 [dir_watcher.py:finish():309] scan: /home/hikari007/dl-torch/Classification/VGGNet/wandb/run-20220519_170304-188kmhvw/files
2022-05-19 17:04:17,979 INFO    SenderThread:10068 [dir_watcher.py:finish():323] scan save: /home/hikari007/dl-torch/Classification/VGGNet/wandb/run-20220519_170304-188kmhvw/files/config.yaml config.yaml
2022-05-19 17:04:17,979 INFO    SenderThread:10068 [file_pusher.py:finish():145] shutting down file pusher
2022-05-19 17:04:17,980 INFO    SenderThread:10068 [file_pusher.py:join():150] waiting for file pusher
2022-05-19 17:04:19,150 INFO    Thread-9  :10068 [upload_job.py:push():137] Uploaded file /home/hikari007/dl-torch/Classification/VGGNet/wandb/run-20220519_170304-188kmhvw/files/config.yaml
2022-05-19 17:04:19,964 INFO    MainThread:10068 [internal.py:handle_exit():80] Internal process exited
